Workbook
Name ClsRecords: RSCLASS!$B$17
Name EqpRecords: RSMEQP!$C$17
Name MNUMRTTY: RSMEQP!$C$19
Name nClDryClasses: RSCLASS!$H$58
Name nClDryTypes: RSMEQP!$I$896
Name nClWashClasses: RSCLASS!$D$58
Name nClWashTypes: RSMEQP!$E$896
Name nCookClasses: RSCLASS!$G$58
Name nCookTypes: RSMEQP!$H$896
Name nCoolClasses: RSCLASS!$C$58
Name nCoolTypes: RSMEQP!$D$896
Name nDishClasses: RSCLASS!$E$58
Name nDishTypes: RSMEQP!$F$896
Name nFrezClasses: RSCLASS!$J$58
Name nFrezTypes: RSMEQP!$K$896
Name nHeatClasses: RSCLASS!$B$58
Name nHeatTypes: RSMEQP!$C$896
Name nRefrClasses: RSCLASS!$I$58
Name nRefrTypes: RSMEQP!$J$896
Name nShellTypes: RSMSHL!$B$14
Name nWatHtClasses: RSCLASS!$F$58
Name nWatHtTypes: RSMEQP!$G$896
Name RSHLDOLLARYR: RSMSHL!$B$16
Name RTEKDOLLARYR: RSMEQP!$C$18
Name ShlRecords: RSMSHL!$B$15
Name xlCLSHBASE: RSMSHL!$O$25:$O$2214
Name xlCLSHEFF: RSMSHL!$M$25:$M$2214
Name xlCWMEF: RSMEQP!$K$25:$K$889
Name xlHTSHBASE: RSMSHL!$N$25:$N$2214
Name xlHTSHEFF: RSMSHL!$L$25:$L$2214
Name xlHVACPNTR: RSMEQP!$I$25:$I$889
Name xlHVCLEQCL: RSMSHL!$F$25:$F$2214
Name xlHVCLEQTY: RSMSHL!$G$25:$G$2214
Name xlHVCOOLFACTOR: RSMSHL!$K$25:$K$2214
Name xlHVFYEAR: RSMSHL!$H$25:$H$2214
Name xlHVHEATFACTOR: RSMSHL!$J$25:$J$2214
Name xlHVHTEQCL: RSMSHL!$D$25:$D$2214
Name xlHVHTEQTY: RSMSHL!$E$25:$E$2214
Name xlHVLYEAR: RSMSHL!$I$25:$I$2214
Name xlHVPACKG: RSMSHL!$S$25:$S$2214
Name xlHVPGNAME: RSMSHL!$T$25:$T$2214
Name xlLOADADJ: RSMEQP!$L$25:$L$889
Name xlRSBTYPE: RSMSHL!$C$25:$C$2214
Name xlRSCENDIV: RSMSHL!$B$25:$B$2214
Name xlRTALPHA: RSCLASS!$N$22:$N$51
Name xlRTBASEFF: RSCLASS!$J$22:$J$51
Name xlRTCENDIV: RSMEQP!$H$25:$H$889
Name xlRTCLENDU: RSCLASS!$C$22:$C$51
Name xlRTCLEQCL: RSCLASS!$D$22:$D$51
Name xlRTCLNAME: RSCLASS!$U$22:$U$51
Name xlRTCLPNTR: RSCLASS!$F$22:$F$51
Name xlRTCLREPL: RSCLASS!$G$22:$G$51
Name xlRTCLTYPT: RSCLASS!$E$22:$E$51
Name xlRTCOSTP1: RSMEQP!$W$25:$W$889
Name xlRTCOSTP2: RSMEQP!$X$25:$X$889
Name xlRTCOSTP3: RSMEQP!$Y$25:$Y$889
Name xlRTECBIAS: RSMEQP!$AC$25:$AC$889
Name xlRTECBTA1: RSMEQP!$Z$25:$Z$889
Name xlRTECBTA2: RSMEQP!$AA$25:$AA$889
Name xlRTECBTA3: RSMEQP!$AB$25:$AB$889

Sheet READ_ME
B2: FILE NAME | C2: Residential Menus for Equipment, Shells, and Subsidies (RSMESS)
B3: USED BY | C3: RTEKREAD subroutine of the National Energy Modeling System (NEMS) Residential Demand Module (RDM)
B4: DEFINITION | C4: Residential sector menu for equipment and shell selection
B6: Tab | C6: Content | D6: Source | E6: Comment | F6: Last Modified
B7: RSCLASS | C7: Residential major end-use equipment class inputs | D7: See tab for sources | E7: Formerly contained in RSCLASS.txt input file | F7: =RSCLASS!$C$3 -> 45484
B8: RSMEQP | C8: Residential major end-use equipment technology menu | D8: See tab for sources | E8: Formerly contained in RSMEQP.txt input file Correct vintage year rows must be present to pull in all applicable values. | F8: =RSMEQP!$D$3 -> 45597
B9: RSMSHL | C9: Residential shell package inputs | D9: See tab for sources | E9: Formerly contained in RSMSHL.txt input file; subsidies are looked up automatically, but correct vintage year rows must be present to pull in all applicable values | F9: =RSMSHL!$C$3 -> 45601
B10: TaxCred&Subs | C10: Equipment and whole-building subsidy lookup tables for federal tax credits, non-federal energy efficiency subsidies, and CPP energy efficiency subsidies | D10: See tab for sources | E10: Updated non-federal energy efficiency rebates based on 2022 data. | F10: ='TaxCred&Subs'!$C$2 -> 45575

Sheet RSCLASS
B2: FILE NAME | C2: RSCLASS
B3: DATE MODIFIED | C3: 45484
B4: DEFINITION | C4: Residential technology equipment class descriptions (pointers and flags for major end-use equipment types)
B5: UNITS | C5: None
B6: DIMENSION | C6: Housing type, Census division, equipment type
B7: SPECIAL CONSTRAINTS | C7: Varies
B8: ORGANIZATION OF DATA | C8: Number classes 1, 2 , 3, ... must match RSM(EQP and SHL) class numbers
C9: Do not change equipment class names (RTCLNAME); RTCLENDU mapping shown in Table 1 and RTFUEL mapping shown in Table 2 of RDM documentation
C10: RTxxxxxx are RESD variable names (also named ranges in Excel); total available number of RSCLASS rows controlled by MNUMRTCL in RTEK includes file
C11: File must be sorted by column one (RTCLENDU) then column two (RTCLEQCL)
B12: SOURCES | C12: Guidehouse and Leidos, EIA - Technology Forecast Updates – Residential and Commercial Building Technologies – Reference Case, March, 2023 (https://www.eia.gov/analysis/studies/buildings/equipcosts/)
C13: Weibull parameters sourced from various DOE rulemaking technical support documents accessed through https://www.energy.gov/eere/buildings/standards-and-test-procedures
B14: COMMENT | C14: Updated base efficiencies and equipment life parameters based on latest technology report and DOE TSDs
B17: =COUNTA(xlRTCLENDU) -> 30 | C17: Number of class records (ClsRecords)
L18: scale (α) | M18: shape (β) | N18: delay (θ) | O18: <- Descriptions from DOE Technical Support Documents
L19: Equipment Life Parameters
B20: End Use/ Class Lookup | C20: End Use | D20: Equipment Class | E20: Type Pointer | F20: Equipment Class Pointer | G20: Replacement Equipment Class | H20: Fuel | I20: Furnace Fan Flag | J20: Base Efficiency | K20: Efficiency Metric | L20: Weibull λ | M20: Weibull K | N20: Alpha | O20: Minimum Equipment Life (Years) | P20: Maximum Equipment Life (Years) | Q20: New Beta | R20: Switching Factor | S20: Replacement Beta | T20: Bias | U20: Equipment Class Name
B21: - | C21: xlRTCLENDU | D21: xlRTCLEQCL | E21: xlRTCLTYPT | F21: xlRTCLPNTR | G21: xlRTCLREPL | H21: xlRTFUEL | I21: xlRTFFAN | J21: xlRTBASEFF | K21: - | L21: xlRTLAMBDA | M21: xlRTK | N21: xlRTALPHA | O21: - | P21: - | Q21: xlRTFCBETA | R21: xlRTSWFACT | S21: xlRTSWBETA | T21: xlRTSWBIAS | U21: xlRTCLNAME | V21: <- RSCLASS variable names
B22: =C22&D22 -> 11 | C22: 1 | D22: 1 | E22: {=MIN(IF(($C22=xlRTTYENDU)*($D22=xlRTTYEQCL),xlRTEQTYPE))} -> 1 | F22: 2 | G22: 3 | H22: 4 | I22: 0 | J22: 0.98 | K22: AFUE | L22: 23.9 | M22: 3.7 | N22: 1 | O22: 15 | P22: 30 | Q22: -0.00108 | R22: 0.2 | S22: -0.00172 | T22: -0.47 | U22: ELEC_RAD
B23: =C23&D23 -> 12 | C23: 1 | D23: 2 | E23: {=MIN(IF(($C23=xlRTTYENDU)*($D23=xlRTTYEQCL),xlRTEQTYPE))} -> 2 | F23: 2 | G23: 0 | H23: 4 | I23: 0 | J23: 2.3153576 | K23: COP | L23: 15.88 | M23: 2 | N23: 1 | O23: 15.3 | P23: 15.3 | Q23: -0.00108 | R23: 0.2 | S23: -0.00172 | T23: -0.1 | U23: ELEC_HP
B24: =C24&D24 -> 13 | C24: 1 | D24: 3 | E24: {=MIN(IF(($C24=xlRTTYENDU)*($D24=xlRTTYEQCL),xlRTEQTYPE))} -> 6 | F24: 1 | G24: 0 | H24: 3 | I24: 1 | J24: 0.8 | K24: AFUE | L24: 22.6 | M24: 3.7 | N24: 1 | O24: 16.1 | P24: 24.7 | Q24: -0.00108 | R24: 0 | S24: -0.00172 | T24: 0 | U24: NG_FA
B25: =C25&D25 -> 14 | C25: 1 | D25: 4 | E25: {=MIN(IF(($C25=xlRTTYENDU)*($D25=xlRTTYEQCL),xlRTEQTYPE))} -> 10 | F25: 1 | G25: 0 | H25: 3 | I25: 1 | J25: 0.82 | K25: AFUE | L25: 28.87 | M25: 2.39 | N25: 1 | O25: 20 | P25: 30 | Q25: -0.00108 | R25: 0 | S25: -0.00172 | T25: 0 | U25: NG_RAD
B26: =C26&D26 -> 15 | C26: 1 | D26: 5 | E26: {=MIN(IF(($C26=xlRTTYENDU)*($D26=xlRTTYEQCL),xlRTEQTYPE))} -> 14 | F26: 2 | G26: 0 | H26: 1 | I26: 0 | J26: 0.83 | K26: AFUE | L26: 23.9 | M26: 3.7 | N26: 1 | O26: 19.7 | P26: 33.1 | Q26: -0.00108 | R26: 0.2 | S26: -0.00172 | T26: -0.27 | U26: KERO_FA
B27: =C27&D27 -> 16 | C27: 1 | D27: 6 | E27: {=MIN(IF(($C27=xlRTTYENDU)*($D27=xlRTTYEQCL),xlRTEQTYPE))} -> 18 | F27: 4 | G27: 3 | H27: 2 | I27: 1 | J27: 0.8 | K27: AFUE | L27: 22.6 | M27: 3.7 | N27: 1 | O27: 16.1 | P27: 24.7 | Q27: -0.00108 | R27: 0.2 | S27: -0.00172 | T27: -0.03 | U27: LPG_FA
B28: =C28&D28 -> 17 | C28: 1 | D28: 7 | E28: {=MIN(IF(($C28=xlRTTYENDU)*($D28=xlRTTYEQCL),xlRTEQTYPE))} -> 22 | F28: 3 | G28: 3 | H28: 1 | I28: 1 | J28: 0.83 | K28: AFUE | L28: 23.9 | M28: 3.7 | N28: 1 | O28: 19.7 | P28: 33.1 | Q28: -0.00108 | R28: 0.2 | S28: -0.00172 | T28: -0.03 | U28: DIST_FA
B29: =C29&D29 -> 18 | C29: 1 | D29: 8 | E29: {=MIN(IF(($C29=xlRTTYENDU)*($D29=xlRTTYEQCL),xlRTEQTYPE))} -> 26 | F29: 3 | G29: 0 | H29: 1 | I29: 1 | J29: 0.84 | K29: AFUE | L29: 26.77 | M29: 2.39 | N29: 1 | O29: 18 | P29: 28 | Q29: -0.00108 | R29: 0.2 | S29: -0.00172 | T29: -0.03 | U29: DIST_RAD
B30: =C30&D30 -> 19 | C30: 1 | D30: 9 | E30: {=MIN(IF(($C30=xlRTTYENDU)*($D30=xlRTTYEQCL),xlRTEQTYPE))} -> 29 | F30: 2 | G30: 3 | H30: 6 | I30: 1 | J30: 0.63 | K30: HHV | L30: 20.23 | M30: 4.11 | N30: 1 | O30: 12 | P30: 25 | Q30: -0.00108 | R30: 0.3 | S30: -0.00172 | T30: -0.27 | U30: WOOD_HT
B31: =C31&D31 -> 110 | C31: 1 | D31: 10 | E31: {=MIN(IF(($C31=xlRTTYENDU)*($D31=xlRTTYEQCL),xlRTEQTYPE))} -> 31 | F31: 2 | G31: 0 | H31: 4 | I31: 0 | J31: 3.1 | K31: COP | L31: 17.04 | M31: 1.64 | N31: 1 | O31: 8 | P31: 20.8 | Q31: -0.00108 | R31: 0 | S31: -0.00172 | T31: -0.1 | U31: GEO_HP
B32: =C32&D32 -> 111 | C32: 1 | D32: 11 | E32: {=MIN(IF(($C32=xlRTTYENDU)*($D32=xlRTTYEQCL),xlRTEQTYPE))} -> 35 | F32: 1 | G32: 0 | H32: 3 | I32: 1 | J32: 1.3 | K32: COP | L32: 15.8 | M32: 7.21 | N32: 0.5 | O32: 12 | P32: 18 | Q32: -0.00108 | R32: 0 | S32: -0.00172 | T32: -0.1 | U32: NG_HP
B33: =C33&D33 -> 21 | C33: 2 | D33: 1 | E33: {=MIN(IF(($C33=xlRTTYENDU)*($D33=xlRTTYEQCL),xlRTEQTYPE))} -> 1 | F33: 0 | G33: 0 | H33: 4 | I33: 0 | J33: 3.1946073 | K33: COP | L33: 9.36 | M33: 2.49 | N33: 1 | O33: 6 | P33: 13 | Q33: 0 | R33: 0.1 | S33: -0.00172 | T33: 0 | U33: ROOM_AIR
... B51: =C51&D51 -> 91 | C51: 9 | D51: 1 | E51: {=MIN(IF(($C51=xlRTTYENDU)*($D51=xlRTTYEQCL),xlRTEQTYPE))} -> 1 | F51: 0 | G51: 0 | H51: 4 | I51: 0 | J51: 483.36048 | K51: kWh/yr | L51: 21.96 | M51: 1.83 | N51: 1 | O51: 21 | P51: 21 | Q51: 0 | R51: 0 | S51: -0.00172 | T51: 0 | U51: FREZ
B52: ^^ Insert new rows above, and extend named ranges if rows are inserted immediately above grey boxes ^^
B54: Used to modify technology parameters in resd.f (labeled !EqpParam)
B55: 1 | C55: 2 | D55: 3 | E55: 4 | F55: 5 | G55: 6 | H55: 7 | I55: 8 | J55: 9
B56: Space Heating | C56: Space Cooling | D56: ClothesWashing | E56: Dishwashing | F56: Water Heating | G56: Cooking | H56: Clothes Drying | I56: Refrigeration | J56: Standalone Freezing
B57: nHeatClasses | C57: nCoolClasses | D57: nClWashClasses | E57: nDishClasses | F57: nWatHtClasses | G57: nCookClasses | H57: nClDryClasses | I57: nRefrClasses | J57: nFrezClasses
B58: {=MAX(IF((xlRTCLENDU=B$55),xlRTCLEQCL,0))} -> 11 | C58: {=MAX(IF((xlRTCLENDU=C$55),xlRTCLEQCL,0))} -> 5 | D58: {=MAX(IF((xlRTCLENDU=D$55),xlRTCLEQCL,0))} -> 1 | E58: {=MAX(IF((xlRTCLENDU=E$55),xlRTCLEQCL,0))} -> 1 | F58: {=MAX(IF((xlRTCLENDU=F$55),xlRTCLEQCL,0))} -> 5 | G58: {=MAX(IF((xlRTCLENDU=G$55),xlRTCLEQCL,0))} -> 3 | H58: {=MAX(IF((xlRTCLENDU=H$55),xlRTCLEQCL,0))} -> 2 | I58: {=MAX(IF((xlRTCLENDU=I$55),xlRTCLEQCL,0))} -> 1 | J58: {=MAX(IF((xlRTCLENDU=J$55),xlRTCLEQCL,0))} -> 1

Sheet RSMEQP
C2: FILE NAME | D2: RSMEQP | L2: Changed value from prior version
C3: DATE MODIFIED | D3: 45597 | L3: New value
C4: DEFINITION | D4: Major end-use equipment technology menu | L4: Verify value
C5: UNITS | D5: Various= see RDM documentation for efficiency units
C6: DIMENSION | D6: End use, equipment class, Census division, end-use technology, vintage
C7: SPECIAL CONSTRAINTS | D7: Must be sorted by column one then column two
D8: End use (xlRTTYENDU) and class number (xlRTTYEQCL) must match xlRTCLENDU and xlRTCLEQCL in RSCLASS.txt input file, respectively
D9: Do not add equipment classes (xlRTTYEQCL)= do not change equipment class names (xlRTTYNAME)
D10: Each xlRTEQTYPE must range the full 2021-2050 projection period and begin with the same RTCLTYPT as in RSCLASS.txt
D11: Set xlRTCENDIV=11 if the entire data row applies to all census divisions; will not apply to ENERGY STAR or higher equipment that receives census division-level non-federal energy efficiency subsidies
C12: ORGANIZATION OF DATA | D12: xlRTxxxxxx labels are RDM variable names (also named ranges in Excel)
C13: SOURCES | D13: Guidehouse and Leidos, EIA - Technology Forecast Updates – Residential and Commercial Building Technologies – Reference Case, March, 2023 (https://www.eia.gov/analysis/studies/buildings/equipcosts/)
C14: COMMENT | D14: Revise base year for 2020 RECS; update equipment costs and characteristics using 2023 technology report; remove instances of Typical equipment that have same performance and cost characteristics as Current Standard or ENERGY STAR; incorporate revised federal minimum efficiency standards and ENERGY STAR specifications
C17: =COUNTA(xlRTTYENDU) -> 865 | D17: Number of technology records (EqpRecords)
C18: 2022 | D18: Equipment cost dollar year (RTEKDOLLARYR)
C19: =EqpRecords+COUNTIF(xlRTCENDIV,11)*8 -> 2097 | D19: Minimum array size parameter (MNUMRTTY)
V21: Cost Trend Function | Z21: Efficiency Choice Model Logit Parameters
C22: End Use | D22: Equipment Class | E22: Equipment Type | F22: First Year | G22: Last Year | H22: Census Division | I22: HVAC Pointer | J22: Type Pointer | K22: Clothes Washer Integrated Modified Energy Factor | L22: Hot Water Load Adjustment | M22: Efficiency | N22: Replacement Cost | O22: New Construction Cost | P22: Federal Replacement Subsidy | Q22: Federal New Construction Subsidy | R22: Non-Federal Replacement Subsidy | S22: Non-Federal New Construction Subsidy | T22: EE Replacement Subsidy | U22: EE New Construction Subsidy | V22: Maturity | W22: Cost Decline Initial Year | X22: Shape Parameter | Y22: Cost Decline | Z22: Beta_1 | AA22: Beta_2 | AB22: Beta_3 | AC22: Bias | AD22: Tech Name
C23: xlRTCLENDU | D23: xlRTCLEQCL | AE23: <- RSCLASS variable names
B24: xlI | C24: xlRTTYENDU | D24: xlRTTYEQCL | E24: xlRTEQTYPE | F24: xlRTINITYR | G24: xlRTLASTYR | H24: xlRTCENDIV | I24: xlHVACPNTR | J24: xlRTTYPNTR | K24: xlCWMEF | L24: xlLOADADJ | M24: xlRTEQEFF | N24: xlRTEQCOST | O24: xlRTRECOST | P24: xlRTEQSUB | Q24: xlRTRESUB | R24: xlRTEQSUBN | S24: xlRTRESUBN | T24: xlRTEQSUB111D | U24: xlRTRESUB111D | V24: xlRTMATURE | W24: xlRTCOSTP1 | X24: xlRTCOSTP2 | Y24: xlRTCOSTP3 | Z24: xlRTECBTA1 | AA24: xlRTECBTA2 | AB24: xlRTECBTA3 | AC24: xlRTECBIAS | AD24: xlRTTYNAME | AE24: <- RSMEQP variable names
B25: 1 | C25: 1 | D25: 1 | E25: 1 | F25: 2020 | G25: 2050 | H25: 11 | I25: 1 | J25: 0 | K25: 0 | L25: 0 | M25: 1 | N25: 1480 | O25: 950 | P25: {=ROUND(IF($F25<='TaxCred&Subs'!$C$49,(IF($C25=2,IF($M25>=IFERROR(INDEX('TaxCred&Subs'!$L$12:$L$47,MATCH(1,($C25&$D25='TaxCred&Subs'!$E$12:$E$47)*($F25='TaxCred&Subs'!$C$12:$C$47),0) ),9999),IFERROR(INDEX('TaxCred&Subs'!$N$12:$N$47,MATCH(1,($C25&$D25='TaxCred&Subs'!$E$12:$E$47)*($F25='TaxCred&Subs'!$C$12:$C$47),0) ),0),0),(IF($M25>=IFERROR(INDEX('TaxCred&Subs'!$H$12:$H$47,MATCH(1,($C25&$D25='TaxCred&Subs'!$D$12:$D$47)*($F25='TaxCred&Subs'!$C$12:$C$47),0) ),9999),IFERROR(INDEX('TaxCred&Subs'!$N$12:$N$47,MATCH(1,($C25&$D25='TaxCred&Subs'!$D$12:$D$47)*($F25='TaxCred&Subs'!$C$12:$C$47),0) ),0),0)))),0)+IF(AND($C25=2,VALUE(RIGHT($AD25,1))>2),(N25-R25)*(IFERROR(INDEX('TaxCred&Subs'!$J$66:$J$99,MATCH(1,($C25&$D25='TaxCred&Subs'!$E$66:$E$99)*($F25='TaxCred&Subs'!$C$66:$C$99),0)),0)),IF(AND($C25=1,VALUE(RIGHT($AD25,1))>2),(N25-R25)*(IFERROR(INDEX('TaxCred&Subs'!$J$66:$J$99,MATCH(1,($C25&$D25='TaxCred&Subs'!$D$66:$D$99)*($F25='TaxCred&Subs'!$C$66:$C$99),0)),0)),IF($C25>2,(N25-R25)*(IFERROR(INDEX('TaxCred&Subs'!$J$66:$J$99,MATCH(1,($C25&$D25='TaxCred&Subs'!$D$66:$D$99)*($F25='TaxCred&Subs'!$C$66:$C$99),0)),0)),0))),0)} -> 0 | Q25: {=ROUND(IF(AND($C25=2,VALUE(RIGHT($AD25,1))>2),(O25-S25)*(IFERROR(INDEX('TaxCred&Subs'!$J$66:$J$99,MATCH(1,($C25&$D25='TaxCred&Subs'!$E$66:$E$99)*($F25='TaxCred&Subs'!$C$66:$C$99),0)),0)),IF(AND($C25=1,VALUE(RIGHT($AD25,1))>2),(O25-S25)*(IFERROR(INDEX('TaxCred&Subs'!$J$66:$J$99,MATCH(1,($C25&$D25='TaxCred&Subs'!$D$66:$D$99)*($F25='TaxCred&Subs'!$C$66:$C$99),0)),0)),IF($C25>2,(O25-S25)*(IFERROR(INDEX('TaxCred&Subs'!$J$66:$J$99,MATCH(1,($C25&$D25='TaxCred&Subs'!$D$66:$D$99)*($F25='TaxCred&Subs'!$C$66:$C$99),0)),0)),0))),0)} -> 0 | R25: {=ROUND(IF(IFERROR(VALUE(RIGHT($AD25,1)),0)>2,IF($C25=8,N25*IFERROR(INDEX('TaxCred&Subs'!$K$139:$S$151,MATCH($C25&$D25&LEFT($AD25,7),'TaxCred&Subs'!$E$139:$E$151,0),MATCH($H25,'TaxCred&Subs'!$K$137:$S$137,0)),0),IF($C25=2,N25*IFERROR(INDEX('TaxCred&Subs'!$K$139:$S$151,MATCH($C25&$D25,'TaxCred&Subs'!$D$139:$D$151,0),MATCH($H25,'TaxCred&Subs'!$K$137:$S$137,0)),0),N25*IFERROR(INDEX('TaxCred&Subs'!$K$139:$S$151,MATCH($C25&$D25,'TaxCred&Subs'!$C$139:$C$151,0),MATCH($H25,'TaxCred&Subs'!$K$137:$S$137,0)),0))),0),0)} -> 0 | S25: {=ROUND(IF(IFERROR(VALUE(RIGHT($AD25,1)),0)>2,IF($C25=8,O25*IFERROR(INDEX('TaxCred&Subs'!$K$139:$S$151,MATCH($C25&$D25&LEFT($AD25,7),'TaxCred&Subs'!$E$139:$E$151,0),MATCH($H25,'TaxCred&Subs'!$K$137:$S$137,0)),0),IF($C25=2,O25*IFERROR(INDEX('TaxCred&Subs'!$K$139:$S$151,MATCH($C25&$D25,'TaxCred&Subs'!$D$139:$D$151,0),MATCH($H25,'TaxCred&Subs'!$K$137:$S$137,0)),0),O25*IFERROR(INDEX('TaxCred&Subs'!$K$139:$S$151,MATCH($C25&$D25,'TaxCred&Subs'!$C$139:$C$151,0),MATCH($H25,'TaxCred&Subs'!$K$137:$S$137,0)),0))),0),0)} -> 0 | T25: =IF($H25=9,IF(R25>0,(N25-P25)*0.15,0),0) -> 0 | U25: =IF($H25=9,IF(S25>0,(O25-Q25)*0.15,0),0) -> 0 | V25: MATURE | W25: 2020 | X25: 1 | Y25: 0 | Z25: -0.005353783 | AA25: -0.082365893 | AB25: 0 | AC25: 0 | AD25: ELEC_RAD2
B26: =B25+1 -> 2 | C26: 1 | D26: 2 | E26: 2 | F26: 2020 | G26: 2022 | H26: 11 | I26: 2 | J26: 0 | K26: 0 | L26: 0 | M26: 2.4032825 | N26: 3365 | O26: 3970 | P26: {=ROUND(IF($F26<='TaxCred&Subs'!$C$49,(IF($C26=2,IF($M26>=IFERROR(INDEX('TaxCred&Subs'!$L$12:$L$47,MATCH(1,($C26&$D26='TaxCred&Subs'!$E$12:$E$47)*($F26='TaxCred&Subs'!$C$12:$C$47),0) ),9999),IFERROR(INDEX('TaxCred&Subs'!$N$12:$N$47,MATCH(1,($C26&$D26='TaxCred&Subs'!$E$12:$E$47)*($F26='TaxCred&Subs'!$C$12:$C$47),0) ),0),0),(IF($M26>=IFERROR(INDEX('TaxCred&Subs'!$H$12:$H$47,MATCH(1,($C26&$D26='TaxCred&Subs'!$D$12:$D$47)*($F26='TaxCred&Subs'!$C$12:$C$47),0) ),9999),IFERROR(INDEX('TaxCred&Subs'!$N$12:$N$47,MATCH(1,($C26&$D26='TaxCred&Subs'!$D$12:$D$47)*($F26='TaxCred&Subs'!$C$12:$C$47),0) ),0),0)))),0)+IF(AND($C26=2,VALUE(RIGHT($AD26,1))>2),(N26-R26)*(IFERROR(INDEX('TaxCred&Subs'!$J$66:$J$99,MATCH(1,($C26&$D26='TaxCred&Subs'!$E$66:$E$99)*($F26='TaxCred&Subs'!$C$66:$C$99),0)),0)),IF(AND($C26=1,VALUE(RIGHT($AD26,1))>2),(N26-R26)*(IFERROR(INDEX('TaxCred&Subs'!$J$66:$J$99,MATCH(1,($C26&$D26='TaxCred&Subs'!$D$66:$D$99)*($F26='TaxCred&Subs'!$C$66:$C$99),0)),0)),IF($C26>2,(N26-R26)*(IFERROR(INDEX('TaxCred&Subs'!$J$66:$J$99,MATCH(1,($C26&$D26='TaxCred&Subs'!$D$66:$D$99)*($F26='TaxCred&Subs'!$C$66:$C$99),0)),0)),0))),0)} -> 0 | Q26: {=ROUND(IF(AND($C26=2,VALUE(RIGHT($AD26,1))>2),(O26-S26)*(IFERROR(INDEX('TaxCred&Subs'!$J$66:$J$99,MATCH(1,($C26&$D26='TaxCred&Subs'!$E$66:$E$99)*($F26='TaxCred&Subs'!$C$66:$C$99),0)),0)),IF(AND($C26=1,VALUE(RIGHT($AD26,1))>2),(O26-S26)*(IFERROR(INDEX('TaxCred&Subs'!$J$66:$J$99,MATCH(1,($C26&$D26='TaxCred&Subs'!$D$66:$D$99)*($F26='TaxCred&Subs'!$C$66:$C$99),0)),0)),IF($C26>2,(O26-S26)*(IFERROR(INDEX('TaxCred&Subs'!$J$66:$J$99,MATCH(1,($C26&$D26='TaxCred&Subs'!$D$66:$D$99)*($F26='TaxCred&Subs'!$C$66:$C$99),0)),0)),0))),0)} -> 0 | R26: {=ROUND(IF(IFERROR(VALUE(RIGHT($AD26,1)),0)>2,IF($C26=8,N26*IFERROR(INDEX('TaxCred&Subs'!$K$139:$S$151,MATCH($C26&$D26&LEFT($AD26,7),'TaxCred&Subs'!$E$139:$E$151,0),MATCH($H26,'TaxCred&Subs'!$K$137:$S$137,0)),0),IF($C26=2,N26*IFERROR(INDEX('TaxCred&Subs'!$K$139:$S$151,MATCH($C26&$D26,'TaxCred&Subs'!$D$139:$D$151,0),MATCH($H26,'TaxCred&Subs'!$K$137:$S$137,0)),0),N26*IFERROR(INDEX('TaxCred&Subs'!$K$139:$S$151,MATCH($C26&$D26,'TaxCred&Subs'!$C$139:$C$151,0),MATCH($H26,'TaxCred&Subs'!$K$137:$S$137,0)),0))),0),0)} -> 0 | S26: {=ROUND(IF(IFERROR(VALUE(RIGHT($AD26,1)),0)>2,IF($C26=8,O26*IFERROR(INDEX('TaxCred&Subs'!$K$139:$S$151,MATCH($C26&$D26&LEFT($AD26,7),'TaxCred&Subs'!$E$139:$E$151,0),MATCH($H26,'TaxCred&Subs'!$K$137:$S$137,0)),0),IF($C26=2,O26*IFERROR(INDEX('TaxCred&Subs'!$K$139:$S$151,MATCH($C26&$D26,'TaxCred&Subs'!$D$139:$D$151,0),MATCH($H26,'TaxCred&Subs'!$K$137:$S$137,0)),0),O26*IFERROR(INDEX('TaxCred&Subs'!$K$139:$S$151,MATCH($C26&$D26,'TaxCred&Subs'!$C$139:$C$151,0),MATCH($H26,'TaxCred&Subs'!$K$137:$S$137,0)),0))),0),0)} -> 0 | T26: =IF($H26=9,IF(R26>0,(N26-P26)*0.15,0),0) -> 0 | U26: =IF($H26=9,IF(S26>0,(O26-Q26)*0.15,0),0) -> 0 | V26: MATURE | W26: 2020 | X26: 1 | Y26: 0 | Z26: -0.00016872968 | AA26: -0.0025958412 | AB26: 0 | AC26: 0 | AD26: ELEC_HP1
B27: =B26+1 -> 3 | C27: 1 | D27: 2 | E27: 2 | F27: 2023 | G27: 2050 | H27: 11 | I27: 2 | J27: 0 | K27: 0 | L27: 0 | M27: 2.5791325 | N27: 3405 | O27: 4110 | P27: {=ROUND(IF($F27<='TaxCred&Subs'!$C$49,(IF($C27=2,IF($M27>=IFERROR(INDEX('TaxCred&Subs'!$L$12:$L$47,MATCH(1,($C27&$D27='TaxCred&Subs'!$E$12:$E$47)*($F27='TaxCred&Subs'!$C$12:$C$47),0) ),9999),IFERROR(INDEX('TaxCred&Subs'!$N$12:$N$47,MATCH(1,($C27&$D27='TaxCred&Subs'!$E$12:$E$47)*($F27='TaxCred&Subs'!$C$12:$C$47),0) ),0),0),(IF($M27>=IFERROR(INDEX('TaxCred&Subs'!$H$12:$H$47,MATCH(1,($C27&$D27='TaxCred&Subs'!$D$12:$D$47)*($F27='TaxCred&Subs'!$C$12:$C$47),0) ),9999),IFERROR(INDEX('TaxCred&Subs'!$N$12:$N$47,MATCH(1,($C27&$D27='TaxCred&Subs'!$D$12:$D$47)*($F27='TaxCred&Subs'!$C$12:$C$47),0) ),0),0)))),0)+IF(AND($C27=2,VALUE(RIGHT($AD27,1))>2),(N27-R27)*(IFERROR(INDEX('TaxCred&Subs'!$J$66:$J$99,MATCH(1,($C27&$D27='TaxCred&Subs'!$E$66:$E$99)*($F27='TaxCred&Subs'!$C$66:$C$99),0)),0)),IF(AND($C27=1,VALUE(RIGHT($AD27,1))>2),(N27-R27)*(IFERROR(INDEX('TaxCred&Subs'!$J$66:$J$99,MATCH(1,($C27&$D27='TaxCred&Subs'!$D$66:$D$99)*($F27='TaxCred&Subs'!$C$66:$C$99),0)),0)),IF($C27>2,(N27-R27)*(IFERROR(INDEX('TaxCred&Subs'!$J$66:$J$99,MATCH(1,($C27&$D27='TaxCred&Subs'!$D$66:$D$99)*($F27='TaxCred&Subs'!$C$66:$C$99),0)),0)),0))),0)} -> 0 | Q27: {=ROUND(IF(AND($C27=2,VALUE(RIGHT($AD27,1))>2),(O27-S27)*(IFERROR(INDEX('TaxCred&Subs'!$J$66:$J$99,MATCH(1,($C27&$D27='TaxCred&Subs'!$E$66:$E$99)*($F27='TaxCred&Subs'!$C$66:$C$99),0)),0)),IF(AND($C27=1,VALUE(RIGHT($AD27,1))>2),(O27-S27)*(IFERROR(INDEX('TaxCred&Subs'!$J$66:$J$99,MATCH(1,($C27&$D27='TaxCred&Subs'!$D$66:$D$99)*($F27='TaxCred&Subs'!$C$66:$C$99),0)),0)),IF($C27>2,(O27-S27)*(IFERROR(INDEX('TaxCred&Subs'!$J$66:$J$99,MATCH(1,($C27&$D27='TaxCred&Subs'!$D$66:$D$99)*($F27='TaxCred&Subs'!$C$66:$C$99),0)),0)),0))),0)} -> 0 | R27: {=ROUND(IF(IFERROR(VALUE(RIGHT($AD27,1)),0)>2,IF($C27=8,N27*IFERROR(INDEX('TaxCred&Subs'!$K$139:$S$151,MATCH($C27&$D27&LEFT($AD27,7),'TaxCred&Subs'!$E$139:$E$151,0),MATCH($H27,'TaxCred&Subs'!$K$137:$S$137,0)),0),IF($C27=2,N27*IFERROR(INDEX('TaxCred&Subs'!$K$139:$S$151,MATCH($C27&$D27,'TaxCred&Subs'!$D$139:$D$151,0),MATCH($H27,'TaxCred&Subs'!$K$137:$S$137,0)),0),N27*IFERROR(INDEX('TaxCred&Subs'!$K$139:$S$151,MATCH($C27&$D27,'TaxCred&Subs'!$C$139:$C$151,0),MATCH($H27,'TaxCred&Subs'!$K$137:$S$137,0)),0))),0),0)} -> 0 | S27: {=ROUND(IF(IFERROR(VALUE(RIGHT($AD27,1)),0)>2,IF($C27=8,O27*IFERROR(INDEX('TaxCred&Subs'!$K$139:$S$151,MATCH($C27&$D27&LEFT($AD27,7),'TaxCred&Subs'!$E$139:$E$151,0),MATCH($H27,'TaxCred&Subs'!$K$137:$S$137,0)),0),IF($C27=2,O27*IFERROR(INDEX('TaxCred&Subs'!$K$139:$S$151,MATCH($C27&$D27,'TaxCred&Subs'!$D$139:$D$151,0),MATCH($H27,'TaxCred&Subs'!$K$137:$S$137,0)),0),O27*IFERROR(INDEX('TaxCred&Subs'!$K$139:$S$151,MATCH($C27&$D27,'TaxCred&Subs'!$C$139:$C$151,0),MATCH($H27,'TaxCred&Subs'!$K$137:$S$137,0)),0))),0),0)} -> 0 | T27: =IF($H27=9,IF(R27>0,(N27-P27)*0.15,0),0) -> 0 | U27: =IF($H27=9,IF(S27>0,(O27-Q27)*0.15,0),0) -> 0 | V27: MATURE | W27: 2020 | X27: 1 | Y27: 0 | Z27: -0.00016872968 | AA27: -0.0025958412 | AB27: 0 | AC27: 0 | AD27: ELEC_HP1
B28: =B27+1 -> 4 | C28: 1 | D28: 2 | E28: 3 | F28: 2020 | G28: 2021 | H28: 11 | I28: 3 | J28: 0 | K28: 0 | L28: 0 | M28: 2.5205158 | N28: 2135 | O28: 4270 | P28: {=ROUND(IF($F28<='TaxCred&Subs'!$C$49,(IF($C28=2,IF($M28>=IFERROR(INDEX('TaxCred&Subs'!$L$12:$L$47,MATCH(1,($C28&$D28='TaxCred&Subs'!$E$12:$E$47)*($F28='TaxCred&Subs'!$C$12:$C$47),0) ),9999),IFERROR(INDEX('TaxCred&Subs'!$N$12:$N$47,MATCH(1,($C28&$D28='TaxCred&Subs'!$E$12:$E$47)*($F28='TaxCred&Subs'!$C$12:$C$47),0) ),0),0),(IF($M28>=IFERROR(INDEX('TaxCred&Subs'!$H$12:$H$47,MATCH(1,($C28&$D28='TaxCred&Subs'!$D$12:$D$47)*($F28='TaxCred&Subs'!$C$12:$C$47),0) ),9999),IFERROR(INDEX('TaxCred&Subs'!$N$12:$N$47,MATCH(1,($C28&$D28='TaxCred&Subs'!$D$12:$D$47)*($F28='TaxCred&Subs'!$C$12:$C$47),0) ),0),0)))),0)+IF(AND($C28=2,VALUE(RIGHT($AD28,1))>2),(N28-R28)*(IFERROR(INDEX('TaxCred&Subs'!$J$66:$J$99,MATCH(1,($C28&$D28='TaxCred&Subs'!$E$66:$E$99)*($F28='TaxCred&Subs'!$C$66:$C$99),0)),0)),IF(AND($C28=1,VALUE(RIGHT($AD28,1))>2),(N28-R28)*(IFERROR(INDEX('TaxCred&Subs'!$J$66:$J$99,MATCH(1,($C28&$D28='TaxCred&Subs'!$D$66:$D$99)*($F28='TaxCred&Subs'!$C$66:$C$99),0)),0)),IF($C28>2,(N28-R28)*(IFERROR(INDEX('TaxCred&Subs'!$J$66:$J$99,MATCH(1,($C28&$D28='TaxCred&Subs'!$D$66:$D$99)*($F28='TaxCred&Subs'!$C$66:$C$99),0)),0)),0))),0)} -> 150 | Q28: {=ROUND(IF(AND($C28=2,VALUE(RIGHT($AD28,1))>2),(O28-S28)*(IFERROR(INDEX('TaxCred&Subs'!$J$66:$J$99,MATCH(1,($C28&$D28='TaxCred&Subs'!$E$66:$E$99)*($F28='TaxCred&Subs'!$C$66:$C$99),0)),0)),IF(AND($C28=1,VALUE(RIGHT($AD28,1))>2),(O28-S28)*(IFERROR(INDEX('TaxCred&Subs'!$J$66:$J$99,MATCH(1,($C28&$D28='TaxCred&Subs'!$D$66:$D$99)*($F28='TaxCred&Subs'!$C$66:$C$99),0)),0)),IF($C28>2,(O28-S28)*(IFERROR(INDEX('TaxCred&Subs'!$J$66:$J$99,MATCH(1,($C28&$D28='TaxCred&Subs'!$D$66:$D$99)*($F28='TaxCred&Subs'!$C$66:$C$99),0)),0)),0))),0)} -> 0 | R28: {=ROUND(IF(IFERROR(VALUE(RIGHT($AD28,1)),0)>2,IF($C28=8,N28*IFERROR(INDEX('TaxCred&Subs'!$K$139:$S$151,MATCH($C28&$D28&LEFT($AD28,7),'TaxCred&Subs'!$E$139:$E$151,0),MATCH($H28,'TaxCred&Subs'!$K$137:$S$137,0)),0),IF($C28=2,N28*IFERROR(INDEX('TaxCred&Subs'!$K$139:$S$151,MATCH($C28&$D28,'TaxCred&Subs'!$D$139:$D$151,0),MATCH($H28,'TaxCred&Subs'!$K$137:$S$137,0)),0),N28*IFERROR(INDEX('TaxCred&Subs'!$K$139:$S$151,MATCH($C28&$D28,'TaxCred&Subs'!$C$139:$C$151,0),MATCH($H28,'TaxCred&Subs'!$K$137:$S$137,0)),0))),0),0)} -> 0 | S28: {=ROUND(IF(IFERROR(VALUE(RIGHT($AD28,1)),0)>2,IF($C28=8,O28*IFERROR(INDEX('TaxCred&Subs'!$K$139:$S$151,MATCH($C28&$D28&LEFT($AD28,7),'TaxCred&Subs'!$E$139:$E$151,0),MATCH($H28,'TaxCred&Subs'!$K$137:$S$137,0)),0),IF($C28=2,O28*IFERROR(INDEX('TaxCred&Subs'!$K$139:$S$151,MATCH($C28&$D28,'TaxCred&Subs'!$D$139:$D$151,0),MATCH($H28,'TaxCred&Subs'!$K$137:$S$137,0)),0),O28*IFERROR(INDEX('TaxCred&Subs'!$K$139:$S$151,MATCH($C28&$D28,'TaxCred&Subs'!$C$139:$C$151,0),MATCH($H28,'TaxCred&Subs'!$K$137:$S$137,0)),0))),0),0)} -> 0 | T28: =IF($H28=9,IF(R28>0,(N28-P28)*0.15,0),0) -> 0 | U28: =IF($H28=9,IF(S28>0,(O28-Q28)*0.15,0),0) -> 0 | V28: MATURE | W28: 2020 | X28: 1 | Y28: 0 | Z28: -0.00016872968 | AA28: -0.0025958412 | AB28: 0 | AC28: 0 | AD28: ELEC_HP2
B29: =B28+1 -> 5 | C29: 1 | D29: 2 | E29: 3 | F29: 2022 | G29: 2022 | H29: 11 | I29: 3 | J29: 0 | K29: 0 | L29: 0 | M29: 2.5205158 | N29: 2135 | O29: 4270 | P29: {=ROUND(IF($F29<='TaxCred&Subs'!$C$49,(IF($C29=2,IF($M29>=IFERROR(INDEX('TaxCred&Subs'!$L$12:$L$47,MATCH(1,($C29&$D29='TaxCred&Subs'!$E$12:$E$47)*($F29='TaxCred&Subs'!$C$12:$C$47),0) ),9999),IFERROR(INDEX('TaxCred&Subs'!$N$12:$N$47,MATCH(1,($C29&$D29='TaxCred&Subs'!$E$12:$E$47)*($F29='TaxCred&Subs'!$C$12:$C$47),0) ),0),0),(IF($M29>=IFERROR(INDEX('TaxCred&Subs'!$H$12:$H$47,MATCH(1,($C29&$D29='TaxCred&Subs'!$D$12:$D$47)*($F29='TaxCred&Subs'!$C$12:$C$47),0) ),9999),IFERROR(INDEX('TaxCred&Subs'!$N$12:$N$47,MATCH(1,($C29&$D29='TaxCred&Subs'!$D$12:$D$47)*($F29='TaxCred&Subs'!$C$12:$C$47),0) ),0),0)))),0)+IF(AND($C29=2,VALUE(RIGHT($AD29,1))>2),(N29-R29)*(IFERROR(INDEX('TaxCred&Subs'!$J$66:$J$99,MATCH(1,($C29&$D29='TaxCred&Subs'!$E$66:$E$99)*($F29='TaxCred&Subs'!$C$66:$C$99),0)),0)),IF(AND($C29=1,VALUE(RIGHT($AD29,1))>2),(N29-R29)*(IFERROR(INDEX('TaxCred&Subs'!$J$66:$J$99,MATCH(1,($C29&$D29='TaxCred&Subs'!$D$66:$D$99)*($F29='TaxCred&Subs'!$C$66:$C$99),0)),0)),IF($C29>2,(N29-R29)*(IFERROR(INDEX('TaxCred&Subs'!$J$66:$J$99,MATCH(1,($C29&$D29='TaxCred&Subs'!$D$66:$D$99)*($F29='TaxCred&Subs'!$C$66:$C$99),0)),0)),0))),0)} -> 1000 | Q29: {=ROUND(IF(AND($C29=2,VALUE(RIGHT($AD29,1))>2),(O29-S29)*(IFERROR(INDEX('TaxCred&Subs'!$J$66:$J$99,MATCH(1,($C29&$D29='TaxCred&Subs'!$E$66:$E$99)*($F29='TaxCred&Subs'!$C$66:$C$99),0)),0)),IF(AND($C29=1,VALUE(RIGHT($AD29,1))>2),(O29-S29)*(IFERROR(INDEX('TaxCred&Subs'!$J$66:$J$99,MATCH(1,($C29&$D29='TaxCred&Subs'!$D$66:$D$99)*($F29='TaxCred&Subs'!$C$66:$C$99),0)),0)),IF($C29>2,(O29-S29)*(IFERROR(INDEX('TaxCred&Subs'!$J$66:$J$99,MATCH(1,($C29&$D29='TaxCred&Subs'!$D$66:$D$99)*($F29='TaxCred&Subs'!$C$66:$C$99),0)),0)),0))),0)} -> 0 | R29: {=ROUND(IF(IFERROR(VALUE(RIGHT($AD29,1)),0)>2,IF($C29=8,N29*IFERROR(INDEX('TaxCred&Subs'!$K$139:$S$151,MATCH($C29&$D29&LEFT($AD29,7),'TaxCred&Subs'!$E$139:$E$151,0),MATCH($H29,'TaxCred&Subs'!$K$137:$S$137,0)),0),IF($C29=2,N29*IFERROR(INDEX('TaxCred&Subs'!$K$139:$S$151,MATCH($C29&$D29,'TaxCred&Subs'!$D$139:$D$151,0),MATCH($H29,'TaxCred&Subs'!$K$137:$S$137,0)),0),N29*IFERROR(INDEX('TaxCred&Subs'!$K$139:$S$151,MATCH($C29&$D29,'TaxCred&Subs'!$C$139:$C$151,0),MATCH($H29,'TaxCred&Subs'!$K$137:$S$137,0)),0))),0),0)} -> 0 | S29: {=ROUND(IF(IFERROR(VALUE(RIGHT($AD29,1)),0)>2,IF($C29=8,O29*IFERROR(INDEX('TaxCred&Subs'!$K$139:$S$151,MATCH($C29&$D29&LEFT($AD29,7),'TaxCred&Subs'!$E$139:$E$151,0),MATCH($H29,'TaxCred&Subs'!$K$137:$S$137,0)),0),IF($C29=2,O29*IFERROR(INDEX('TaxCred&Subs'!$K$139:$S$151,MATCH($C29&$D29,'TaxCred&Subs'!$D$139:$D$151,0),MATCH($H29,'TaxCred&Subs'!$K$137:$S$137,0)),0),O29*IFERROR(INDEX('TaxCred&Subs'!$K$139:$S$151,MATCH($C29&$D29,'TaxCred&Subs'!$C$139:$C$151,0),MATCH($H29,'TaxCred&Subs'!$K$137:$S$137,0)),0))),0),0)} -> 0 | T29: =IF($H29=9,IF(R29>0,(N29-P29)*0.15,0),0) -> 0 | U29: =IF($H29=9,IF(S29>0,(O29-Q29)*0.15,0),0) -> 0 | V29: MATURE | W29: 2020 | X29: 1 | Y29: 0 | Z29: -0.00016872968 | AA29: -0.0025958412 | AB29: 0 | AC29: 0 | AD29: ELEC_HP2
B30: =B29+1 -> 6 | C30: 1 | D30: 2 | E30: 3 | F30: 2023 | G30: 2032 | H30: 11 | I30: 3 | J30: 0 | K30: 0 | L30: 0 | M30: 2.6963658 | N30: 3470 | O30: 4380 | P30: {=ROUND(IF($F30<='TaxCred&Subs'!$C$49,(IF($C30=2,IF($M30>=IFERROR(INDEX('TaxCred&Subs'!$L$12:$L$47,MATCH(1,($C30&$D30='TaxCred&Subs'!$E$12:$E$47)*($F30='TaxCred&Subs'!$C$12:$C$47),0) ),9999),IFERROR(INDEX('TaxCred&Subs'!$N$12:$N$47,MATCH(1,($C30&$D30='TaxCred&Subs'!$E$12:$E$47)*($F30='TaxCred&Subs'!$C$12:$C$47),0) ),0),0),(IF($M30>=IFERROR(INDEX('TaxCred&Subs'!$H$12:$H$47,MATCH(1,($C30&$D30='TaxCred&Subs'!$D$12:$D$47)*($F30='TaxCred&Subs'!$C$12:$C$47),0) ),9999),IFERROR(INDEX('TaxCred&Subs'!$N$12:$N$47,MATCH(1,($C30&$D30='TaxCred&Subs'!$D$12:$D$47)*($F30='TaxCred&Subs'!$C$12:$C$47),0) ),0),0)))),0)+IF(AND($C30=2,VALUE(RIGHT($AD30,1))>2),(N30-R30)*(IFERROR(INDEX('TaxCred&Subs'!$J$66:$J$99,MATCH(1,($C30&$D30='TaxCred&Subs'!$E$66:$E$99)*($F30='TaxCred&Subs'!$C$66:$C$99),0)),0)),IF(AND($C30=1,VALUE(RIGHT($AD30,1))>2),(N30-R30)*(IFERROR(INDEX('TaxCred&Subs'!$J$66:$J$99,MATCH(1,($C30&$D30='TaxCred&Subs'!$D$66:$D$99)*($F30='TaxCred&Subs'!$C$66:$C$99),0)),0)),IF($C30>2,(N30-R30)*(IFERROR(INDEX('TaxCred&Subs'!$J$66:$J$99,MATCH(1,($C30&$D30='TaxCred&Subs'!$D$66:$D$99)*($F30='TaxCred&Subs'!$C$66:$C$99),0)),0)),0))),0)} -> 1000 | Q30: {=ROUND(IF(AND($C30=2,VALUE(RIGHT($AD30,1))>2),(O30-S30)*(IFERROR(INDEX('TaxCred&Subs'!$J$66:$J$99,MATCH(1,($C30&$D30='TaxCred&Subs'!$E$66:$E$99)*($F30='TaxCred&Subs'!$C$66:$C$99),0)),0)),IF(AND($C30=1,VALUE(RIGHT($AD30,1))>2),(O30-S30)*(IFERROR(INDEX('TaxCred&Subs'!$J$66:$J$99,MATCH(1,($C30&$D30='TaxCred&Subs'!$D$66:$D$99)*($F30='TaxCred&Subs'!$C$66:$C$99),0)),0)),IF($C30>2,(O30-S30)*(IFERROR(INDEX('TaxCred&Subs'!$J$66:$J$99,MATCH(1,($C30&$D30='TaxCred&Subs'!$D$66:$D$99)*($F30='TaxCred&Subs'!$C$66:$C$99),0)),0)),0))),0)} -> 0 | R30: {=ROUND(IF(IFERROR(VALUE(RIGHT($AD30,1)),0)>2,IF($C30=8,N30*IFERROR(INDEX('TaxCred&Subs'!$K$139:$S$151,MATCH($C30&$D30&LEFT($AD30,7),'TaxCred&Subs'!$E$139:$E$151,0),MATCH($H30,'TaxCred&Subs'!$K$137:$S$137,0)),0),IF($C30=2,N30*IFERROR(INDEX('TaxCred&Subs'!$K$139:$S$151,MATCH($C30&$D30,'TaxCred&Subs'!$D$139:$D$151,0),MATCH($H30,'TaxCred&Subs'!$K$137:$S$137,0)),0),N30*IFERROR(INDEX('TaxCred&Subs'!$K$139:$S$151,MATCH($C30&$D30,'TaxCred&Subs'!$C$139:$C$151,0),MATCH($H30,'TaxCred&Subs'!$K$137:$S$137,0)),0))),0),0)} -> 0 | S30: {=ROUND(IF(IFERROR(VALUE(RIGHT($AD30,1)),0)>2,IF($C30=8,O30*IFERROR(INDEX('TaxCred&Subs'!$K$139:$S$151,MATCH($C30&$D30&LEFT($AD30,7),'TaxCred&Subs'!$E$139:$E$151,0),MATCH($H30,'TaxCred&Subs'!$K$137:$S$137,0)),0),IF($C30=2,O30*IFERROR(INDEX('TaxCred&Subs'!$K$139:$S$151,MATCH($C30&$D30,'TaxCred&Subs'!$D$139:$D$151,0),MATCH($H30,'TaxCred&Subs'!$K$137:$S$137,0)),0),O30*IFERROR(INDEX('TaxCred&Subs'!$K$139:$S$151,MATCH($C30&$D30,'TaxCred&Subs'!$C$139:$C$151,0),MATCH($H30,'TaxCred&Subs'!$K$137:$S$137,0)),0))),0),0)} -> 0 | T30: =IF($H30=9,IF(R30>0,(N30-P30)*0.15,0),0) -> 0 | U30: =IF($H30=9,IF(S30>0,(O30-Q30)*0.15,0),0) -> 0 | V30: MATURE | W30: 2020 | X30: 1 | Y30: 0 | Z30: -0.00016872968 | AA30: -0.0025958412 | AB30: 0 | AC30: 0 | AD30: ELEC_HP2
B31: =B30+1 -> 7 | C31: 1 | D31: 2 | E31: 3 | F31: 2033 | G31: 2039 | H31: 11 | I31: 3 | J31: 0 | K31: 0 | L31: 0 | M31: 2.6963658 | N31: 3470 | O31: 4380 | P31: {=ROUND(IF($F31<='TaxCred&Subs'!$C$49,(IF($C31=2,IF($M31>=IFERROR(INDEX('TaxCred&Subs'!$L$12:$L$47,MATCH(1,($C31&$D31='TaxCred&Subs'!$E$12:$E$47)*($F31='TaxCred&Subs'!$C$12:$C$47),0) ),9999),IFERROR(INDEX('TaxCred&Subs'!$N$12:$N$47,MATCH(1,($C31&$D31='TaxCred&Subs'!$E$12:$E$47)*($F31='TaxCred&Subs'!$C$12:$C$47),0) ),0),0),(IF($M31>=IFERROR(INDEX('TaxCred&Subs'!$H$12:$H$47,MATCH(1,($C31&$D31='TaxCred&Subs'!$D$12:$D$47)*($F31='TaxCred&Subs'!$C$12:$C$47),0) ),9999),IFERROR(INDEX('TaxCred&Subs'!$N$12:$N$47,MATCH(1,($C31&$D31='TaxCred&Subs'!$D$12:$D$47)*($F31='TaxCred&Subs'!$C$12:$C$47),0) ),0),0)))),0)+IF(AND($C31=2,VALUE(RIGHT($AD31,1))>2),(N31-R31)*(IFERROR(INDEX('TaxCred&Subs'!$J$66:$J$99,MATCH(1,($C31&$D31='TaxCred&Subs'!$E$66:$E$99)*($F31='TaxCred&Subs'!$C$66:$C$99),0)),0)),IF(AND($C31=1,VALUE(RIGHT($AD31,1))>2),(N31-R31)*(IFERROR(INDEX('TaxCred&Subs'!$J$66:$J$99,MATCH(1,($C31&$D31='TaxCred&Subs'!$D$66:$D$99)*($F31='TaxCred&Subs'!$C$66:$C$99),0)),0)),IF($C31>2,(N31-R31)*(IFERROR(INDEX('TaxCred&Subs'!$J$66:$J$99,MATCH(1,($C31&$D31='TaxCred&Subs'!$D$66:$D$99)*($F31='TaxCred&Subs'!$C$66:$C$99),0)),0)),0))),0)} -> 0 | Q31: {=ROUND(IF(AND($C31=2,VALUE(RIGHT($AD31,1))>2),(O31-S31)*(IFERROR(INDEX('TaxCred&Subs'!$J$66:$J$99,MATCH(1,($C31&$D31='TaxCred&Subs'!$E$66:$E$99)*($F31='TaxCred&Subs'!$C$66:$C$99),0)),0)),IF(AND($C31=1,VALUE(RIGHT($AD31,1))>2),(O31-S31)*(IFERROR(INDEX('TaxCred&Subs'!$J$66:$J$99,MATCH(1,($C31&$D31='TaxCred&Subs'!$D$66:$D$99)*($F31='TaxCred&Subs'!$C$66:$C$99),0)),0)),IF($C31>2,(O31-S31)*(IFERROR(INDEX('TaxCred&Subs'!$J$66:$J$99,MATCH(1,($C31&$D31='TaxCred&Subs'!$D$66:$D$99)*($F31='TaxCred&Subs'!$C$66:$C$99),0)),0)),0))),0)} -> 0 | R31: {=ROUND(IF(IFERROR(VALUE(RIGHT($AD31,1)),0)>2,IF($C31=8,N31*IFERROR(INDEX('TaxCred&Subs'!$K$139:$S$151,MATCH($C31&$D31&LEFT($AD31,7),'TaxCred&Subs'!$E$139:$E$151,0),MATCH($H31,'TaxCred&Subs'!$K$137:$S$137,0)),0),IF($C31=2,N31*IFERROR(INDEX('TaxCred&Subs'!$K$139:$S$151,MATCH($C31&$D31,'TaxCred&Subs'!$D$139:$D$151,0),MATCH($H31,'TaxCred&Subs'!$K$137:$S$137,0)),0),N31*IFERROR(INDEX('TaxCred&Subs'!$K$139:$S$151,MATCH($C31&$D31,'TaxCred&Subs'!$C$139:$C$151,0),MATCH($H31,'TaxCred&Subs'!$K$137:$S$137,0)),0))),0),0)} -> 0 | S31: {=ROUND(IF(IFERROR(VALUE(RIGHT($AD31,1)),0)>2,IF($C31=8,O31*IFERROR(INDEX('TaxCred&Subs'!$K$139:$S$151,MATCH($C31&$D31&LEFT($AD31,7),'TaxCred&Subs'!$E$139:$E$151,0),MATCH($H31,'TaxCred&Subs'!$K$137:$S$137,0)),0),IF($C31=2,O31*IFERROR(INDEX('TaxCred&Subs'!$K$139:$S$151,MATCH($C31&$D31,'TaxCred&Subs'!$D$139:$D$151,0),MATCH($H31,'TaxCred&Subs'!$K$137:$S$137,0)),0),O31*IFERROR(INDEX('TaxCred&Subs'!$K$139:$S$151,MATCH($C31&$D31,'TaxCred&Subs'!$C$139:$C$151,0),MATCH($H31,'TaxCred&Subs'!$K$137:$S$137,0)),0))),0),0)} -> 0 | T31: =IF($H31=9,IF(R31>0,(N31-P31)*0.15,0),0) -> 0 | U31: =IF($H31=9,IF(S31>0,(O31-Q31)*0.15,0),0) -> 0 | V31: MATURE | W31: 2020 | X31: 1 | Y31: 0 | Z31: -0.00016872968 | AA31: -0.0025958412 | AB31: 0 | AC31: 0 | AD31: ELEC_HP2
B32: =B31+1 -> 8 | C32: 1 | D32: 2 | E32: 3 | F32: 2040 | G32: 2050 | H32: 11 | I32: 3 | J32: 0 | K32: 0 | L32: 0 | M32: 2.7256741 | N32: 3620 | O32: 5000 | P32: {=ROUND(IF($F32<='TaxCred&Subs'!$C$49,(IF($C32=2,IF($M32>=IFERROR(INDEX('TaxCred&Subs'!$L$12:$L$47,MATCH(1,($C32&$D32='TaxCred&Subs'!$E$12:$E$47)*($F32='TaxCred&Subs'!$C$12:$C$47),0) ),9999),IFERROR(INDEX('TaxCred&Subs'!$N$12:$N$47,MATCH(1,($C32&$D32='TaxCred&Subs'!$E$12:$E$47)*($F32='TaxCred&Subs'!$C$12:$C$47),0) ),0),0),(IF($M32>=IFERROR(INDEX('TaxCred&Subs'!$H$12:$H$47,MATCH(1,($C32&$D32='TaxCred&Subs'!$D$12:$D$47)*($F32='TaxCred&Subs'!$C$12:$C$47),0) ),9999),IFERROR(INDEX('TaxCred&Subs'!$N$12:$N$47,MATCH(1,($C32&$D32='TaxCred&Subs'!$D$12:$D$47)*($F32='TaxCred&Subs'!$C$12:$C$47),0) ),0),0)))),0)+IF(AND($C32=2,VALUE(RIGHT($AD32,1))>2),(N32-R32)*(IFERROR(INDEX('TaxCred&Subs'!$J$66:$J$99,MATCH(1,($C32&$D32='TaxCred&Subs'!$E$66:$E$99)*($F32='TaxCred&Subs'!$C$66:$C$99),0)),0)),IF(AND($C32=1,VALUE(RIGHT($AD32,1))>2),(N32-R32)*(IFERROR(INDEX('TaxCred&Subs'!$J$66:$J$99,MATCH(1,($C32&$D32='TaxCred&Subs'!$D$66:$D$99)*($F32='TaxCred&Subs'!$C$66:$C$99),0)),0)),IF($C32>2,(N32-R32)*(IFERROR(INDEX('TaxCred&Subs'!$J$66:$J$99,MATCH(1,($C32&$D32='TaxCred&Subs'!$D$66:$D$99)*($F32='TaxCred&Subs'!$C$66:$C$99),0)),0)),0))),0)} -> 0 | Q32: {=ROUND(IF(AND($C32=2,VALUE(RIGHT($AD32,1))>2),(O32-S32)*(IFERROR(INDEX('TaxCred&Subs'!$J$66:$J$99,MATCH(1,($C32&$D32='TaxCred&Subs'!$E$66:$E$99)*($F32='TaxCred&Subs'!$C$66:$C$99),0)),0)),IF(AND($C32=1,VALUE(RIGHT($AD32,1))>2),(O32-S32)*(IFERROR(INDEX('TaxCred&Subs'!$J$66:$J$99,MATCH(1,($C32&$D32='TaxCred&Subs'!$D$66:$D$99)*($F32='TaxCred&Subs'!$C$66:$C$99),0)),0)),IF($C32>2,(O32-S32)*(IFERROR(INDEX('TaxCred&Subs'!$J$66:$J$99,MATCH(1,($C32&$D32='TaxCred&Subs'!$D$66:$D$99)*($F32='TaxCred&Subs'!$C$66:$C$99),0)),0)),0))),0)} -> 0 | R32: {=ROUND(IF(IFERROR(VALUE(RIGHT($AD32,1)),0)>2,IF($C32=8,N32*IFERROR(INDEX('TaxCred&Subs'!$K$139:$S$151,MATCH($C32&$D32&LEFT($AD32,7),'TaxCred&Subs'!$E$139:$E$151,0),MATCH($H32,'TaxCred&Subs'!$K$137:$S$137,0)),0),IF($C32=2,N32*IFERROR(INDEX('TaxCred&Subs'!$K$139:$S$151,MATCH($C32&$D32,'TaxCred&Subs'!$D$139:$D$151,0),MATCH($H32,'TaxCred&Subs'!$K$137:$S$137,0)),0),N32*IFERROR(INDEX('TaxCred&Subs'!$K$139:$S$151,MATCH($C32&$D32,'TaxCred&Subs'!$C$139:$C$151,0),MATCH($H32,'TaxCred&Subs'!$K$137:$S$137,0)),0))),0),0)} -> 0 | S32: {=ROUND(IF(IFERROR(VALUE(RIGHT($AD32,1)),0)>2,IF($C32=8,O32*IFERROR(INDEX('TaxCred&Subs'!$K$139:$S$151,MATCH($C32&$D32&LEFT($AD32,7),'TaxCred&Subs'!$E$139:$E$151,0),MATCH($H32,'TaxCred&Subs'!$K$137:$S$137,0)),0),IF($C32=2,O32*IFERROR(INDEX('TaxCred&Subs'!$K$139:$S$151,MATCH($C32&$D32,'TaxCred&Subs'!$D$139:$D$151,0),MATCH($H32,'TaxCred&Subs'!$K$137:$S$137,0)),0),O32*IFERROR(INDEX('TaxCred&Subs'!$K$139:$S$151,MATCH($C32&$D32,'TaxCred&Subs'!$C$139:$C$151,0),MATCH($H32,'TaxCred&Subs'!$K$137:$S$137,0)),0))),0),0)} -> 0 | T32: =IF($H32=9,IF(R32>0,(N32-P32)*0.15,0),0) -> 0 | U32: =IF($H32=9,IF(S32>0,(O32-Q32)*0.15,0),0) -> 0 | V32: MATURE | W32: 2020 | X32: 1 | Y32: 0 | Z32: -0.00016872968 | AA32: -0.0025958412 | AB32: 0 | AC32: 0 | AD32: ELEC_HP2
B33: =B32+1 -> 9 | C33: 1 | D33: 2 | E33: 4 | F33: 2020 | G33: 2021 | H33: 1 | I33: 4 | J33: 0 | K33: 0 | L33: 0 | M33: 2.4912075 | N33: 3405 | O33: 4110 | P33: {=ROUND(IF($F33<='TaxCred&Subs'!$C$49,(IF($C33=2,IF($M33>=IFERROR(INDEX('TaxCred&Subs'!$L$12:$L$47,MATCH(1,($C33&$D33='TaxCred&Subs'!$E$12:$E$47)*($F33='TaxCred&Subs'!$C$12:$C$47),0) ),9999),IFERROR(INDEX('TaxCred&Subs'!$N$12:$N$47,MATCH(1,($C33&$D33='TaxCred&Subs'!$E$12:$E$47)*($F33='TaxCred&Subs'!$C$12:$C$47),0) ),0),0),(IF($M33>=IFERROR(INDEX('TaxCred&Subs'!$H$12:$H$47,MATCH(1,($C33&$D33='TaxCred&Subs'!$D$12:$D$47)*($F33='TaxCred&Subs'!$C$12:$C$47),0) ),9999),IFERROR(INDEX('TaxCred&Subs'!$N$12:$N$47,MATCH(1,($C33&$D33='TaxCred&Subs'!$D$12:$D$47)*($F33='TaxCred&Subs'!$C$12:$C$47),0) ),0),0)))),0)+IF(AND($C33=2,VALUE(RIGHT($AD33,1))>2),(N33-R33)*(IFERROR(INDEX('TaxCred&Subs'!$J$66:$J$99,MATCH(1,($C33&$D33='TaxCred&Subs'!$E$66:$E$99)*($F33='TaxCred&Subs'!$C$66:$C$99),0)),0)),IF(AND($C33=1,VALUE(RIGHT($AD33,1))>2),(N33-R33)*(IFERROR(INDEX('TaxCred&Subs'!$J$66:$J$99,MATCH(1,($C33&$D33='TaxCred&Subs'!$D$66:$D$99)*($F33='TaxCred&Subs'!$C$66:$C$99),0)),0)),IF($C33>2,(N33-R33)*(IFERROR(INDEX('TaxCred&Subs'!$J$66:$J$99,MATCH(1,($C33&$D33='TaxCred&Subs'!$D$66:$D$99)*($F33='TaxCred&Subs'!$C$66:$C$99),0)),0)),0))),0)} -> 150 | Q33: {=ROUND(IF(AND($C33=2,VALUE(RIGHT($AD33,1))>2),(O33-S33)*(IFERROR(INDEX('TaxCred&Subs'!$J$66:$J$99,MATCH(1,($C33&$D33='TaxCred&Subs'!$E$66:$E$99)*($F33='TaxCred&Subs'!$C$66:$C$99),0)),0)),IF(AND($C33=1,VALUE(RIGHT($AD33,1))>2),(O33-S33)*(IFERROR(INDEX('TaxCred&Subs'!$J$66:$J$99,MATCH(1,($C33&$D33='TaxCred&Subs'!$D$66:$D$99)*($F33='TaxCred&Subs'!$C$66:$C$99),0)),0)),IF($C33>2,(O33-S33)*(IFERROR(INDEX('TaxCred&Subs'!$J$66:$J$99,MATCH(1,($C33&$D33='TaxCred&Subs'!$D$66:$D$99)*($F33='TaxCred&Subs'!$C$66:$C$99),0)),0)),0))),0)} -> 0 | R33: {=ROUND(IF(IFERROR(VALUE(RIGHT($AD33,1)),0)>2,IF($C33=8,N33*IFERROR(INDEX('TaxCred&Subs'!$K$139:$S$151,MATCH($C33&$D33&LEFT($AD33,7),'TaxCred&Subs'!$E$139:$E$151,0),MATCH($H33,'TaxCred&Subs'!$K$137:$S$137,0)),0),IF($C33=2,N33*IFERROR(INDEX('TaxCred&Subs'!$K$139:$S$151,MATCH($C33&$D33,'TaxCred&Subs'!$D$139:$D$151,0),MATCH($H33,'TaxCred&Subs'!$K$137:$S$137,0)),0),N33*IFERROR(INDEX('TaxCred&Subs'!$K$139:$S$151,MATCH($C33&$D33,'TaxCred&Subs'!$C$139:$C$151,0),MATCH($H33,'TaxCred&Subs'!$K$137:$S$137,0)),0))),0),0)} -> 492 | S33: {=ROUND(IF(IFERROR(VALUE(RIGHT($AD33,1)),0)>2,IF($C33=8,O33*IFERROR(INDEX('TaxCred&Subs'!$K$139:$S$151,MATCH($C33&$D33&LEFT($AD33,7),'TaxCred&Subs'!$E$139:$E$151,0),MATCH($H33,'TaxCred&Subs'!$K$137:$S$137,0)),0),IF($C33=2,O33*IFERROR(INDEX('TaxCred&Subs'!$K$139:$S$151,MATCH($C33&$D33,'TaxCred&Subs'!$D$139:$D$151,0),MATCH($H33,'TaxCred&Subs'!$K$137:$S$137,0)),0),O33*IFERROR(INDEX('TaxCred&Subs'!$K$139:$S$151,MATCH($C33&$D33,'TaxCred&Subs'!$C$139:$C$151,0),MATCH($H33,'TaxCred&Subs'!$K$137:$S$137,0)),0))),0),0)} -> 593 | T33: =IF($H33=9,IF(R33>0,(N33-P33)*0.15,0),0) -> 0 | U33: =IF($H33=9,IF(S33>0,(O33-Q33)*0.15,0),0) -> 0 | V33: MATURE | W33: 2020 | X33: 1 | Y33: 0 | Z33: -0.00020762473 | AA33: -0.0031942266 | AB33: 0 | AC33: 0 | AD33: ELEC_HP3
B34: =B33+1 -> 10 | C34: 1 | D34: 2 | E34: 4 | F34: 2020 | G34: 2021 | H34: 2 | I34: 4 | J34: 0 | K34: 0 | L34: 0 | M34: 2.4912075 | N34: 3405 | O34: 4110 | P34: {=ROUND(IF($F34<='TaxCred&Subs'!$C$49,(IF($C34=2,IF($M34>=IFERROR(INDEX('TaxCred&Subs'!$L$12:$L$47,MATCH(1,($C34&$D34='TaxCred&Subs'!$E$12:$E$47)*($F34='TaxCred&Subs'!$C$12:$C$47),0) ),9999),IFERROR(INDEX('TaxCred&Subs'!$N$12:$N$47,MATCH(1,($C34&$D34='TaxCred&Subs'!$E$12:$E$47)*($F34='TaxCred&Subs'!$C$12:$C$47),0) ),0),0),(IF($M34>=IFERROR(INDEX('TaxCred&Subs'!$H$12:$H$47,MATCH(1,($C34&$D34='TaxCred&Subs'!$D$12:$D$47)*($F34='TaxCred&Subs'!$C$12:$C$47),0) ),9999),IFERROR(INDEX('TaxCred&Subs'!$N$12:$N$47,MATCH(1,($C34&$D34='TaxCred&Subs'!$D$12:$D$47)*($F34='TaxCred&Subs'!$C$12:$C$47),0) ),0),0)))),0)+IF(AND($C34=2,VALUE(RIGHT($AD34,1))>2),(N34-R34)*(IFERROR(INDEX('TaxCred&Subs'!$J$66:$J$99,MATCH(1,($C34&$D34='TaxCred&Subs'!$E$66:$E$99)*($F34='TaxCred&Subs'!$C$66:$C$99),0)),0)),IF(AND($C34=1,VALUE(RIGHT($AD34,1))>2),(N34-R34)*(IFERROR(INDEX('TaxCred&Subs'!$J$66:$J$99,MATCH(1,($C34&$D34='TaxCred&Subs'!$D$66:$D$99)*($F34='TaxCred&Subs'!$C$66:$C$99),0)),0)),IF($C34>2,(N34-R34)*(IFERROR(INDEX('TaxCred&Subs'!$J$66:$J$99,MATCH(1,($C34&$D34='TaxCred&Subs'!$D$66:$D$99)*($F34='TaxCred&Subs'!$C$66:$C$99),0)),0)),0))),0)} -> 150 | Q34: {=ROUND(IF(AND($C34=2,VALUE(RIGHT($AD34,1))>2),(O34-S34)*(IFERROR(INDEX('TaxCred&Subs'!$J$66:$J$99,MATCH(1,($C34&$D34='TaxCred&Subs'!$E$66:$E$99)*($F34='TaxCred&Subs'!$C$66:$C$99),0)),0)),IF(AND($C34=1,VALUE(RIGHT($AD34,1))>2),(O34-S34)*(IFERROR(INDEX('TaxCred&Subs'!$J$66:$J$99,MATCH(1,($C34&$D34='TaxCred&Subs'!$D$66:$D$99)*($F34='TaxCred&Subs'!$C$66:$C$99),0)),0)),IF($C34>2,(O34-S34)*(IFERROR(INDEX('TaxCred&Subs'!$J$66:$J$99,MATCH(1,($C34&$D34='TaxCred&Subs'!$D$66:$D$99)*($F34='TaxCred&Subs'!$C$66:$C$99),0)),0)),0))),0)} -> 0 | R34: {=ROUND(IF(IFERROR(VALUE(RIGHT($AD34,1)),0)>2,IF($C34=8,N34*IFERROR(INDEX('TaxCred&Subs'!$K$139:$S$151,MATCH($C34&$D34&LEFT($AD34,7),'TaxCred&Subs'!$E$139:$E$151,0),MATCH($H34,'TaxCred&Subs'!$K$137:$S$137,0)),0),IF($C34=2,N34*IFERROR(INDEX('TaxCred&Subs'!$K$139:$S$151,MATCH($C34&$D34,'TaxCred&Subs'!$D$139:$D$151,0),MATCH($H34,'TaxCred&Subs'!$K$137:$S$137,0)),0),N34*IFERROR(INDEX('TaxCred&Subs'!$K$139:$S$151,MATCH($C34&$D34,'TaxCred&Subs'!$C$139:$C$151,0),MATCH($H34,'TaxCred&Subs'!$K$137:$S$137,0)),0))),0),0)} -> 178 | S34: {=ROUND(IF(IFERROR(VALUE(RIGHT($AD34,1)),0)>2,IF($C34=8,O34*IFERROR(INDEX('TaxCred&Subs'!$K$139:$S$151,MATCH($C34&$D34&LEFT($AD34,7),'TaxCred&Subs'!$E$139:$E$151,0),MATCH($H34,'TaxCred&Subs'!$K$137:$S$137,0)),0),IF($C34=2,O34*IFERROR(INDEX('TaxCred&Subs'!$K$139:$S$151,MATCH($C34&$D34,'TaxCred&Subs'!$D$139:$D$151,0),MATCH($H34,'TaxCred&Subs'!$K$137:$S$137,0)),0),O34*IFERROR(INDEX('TaxCred&Subs'!$K$139:$S$151,MATCH($C34&$D34,'TaxCred&Subs'!$C$139:$C$151,0),MATCH($H34,'TaxCred&Subs'!$K$137:$S$137,0)),0))),0),0)} -> 215 | T34: =IF($H34=9,IF(R34>0,(N34-P34)*0.15,0),0) -> 0 | U34: =IF($H34=9,IF(S34>0,(O34-Q34)*0.15,0),0) -> 0 | V34: MATURE | W34: 2020 | X34: 1 | Y34: 0 | Z34: -0.00020762473 | AA34: -0.0031942266 | AB34: 0 | AC34: 0 | AD34: ELEC_HP3
B35: =B34+1 -> 11 | C35: 1 | D35: 2 | E35: 4 | F35: 2020 | G35: 2021 | H35: 3 | I35: 4 | J35: 0 | K35: 0 | L35: 0 | M35: 2.4912075 | N35: 3405 | O35: 4110 | P35: {=ROUND(IF($F35<='TaxCred&Subs'!$C$49,(IF($C35=2,IF($M35>=IFERROR(INDEX('TaxCred&Subs'!$L$12:$L$47,MATCH(1,($C35&$D35='TaxCred&Subs'!$E$12:$E$47)*($F35='TaxCred&Subs'!$C$12:$C$47),0) ),9999),IFERROR(INDEX('TaxCred&Subs'!$N$12:$N$47,MATCH(1,($C35&$D35='TaxCred&Subs'!$E$12:$E$47)*($F35='TaxCred&Subs'!$C$12:$C$47),0) ),0),0),(IF($M35>=IFERROR(INDEX('TaxCred&Subs'!$H$12:$H$47,MATCH(1,($C35&$D35='TaxCred&Subs'!$D$12:$D$47)*($F35='TaxCred&Subs'!$C$12:$C$47),0) ),9999),IFERROR(INDEX('TaxCred&Subs'!$N$12:$N$47,MATCH(1,($C35&$D35='TaxCred&Subs'!$D$12:$D$47)*($F35='TaxCred&Subs'!$C$12:$C$47),0) ),0),0)))),0)+IF(AND($C35=2,VALUE(RIGHT($AD35,1))>2),(N35-R35)*(IFERROR(INDEX('TaxCred&Subs'!$J$66:$J$99,MATCH(1,($C35&$D35='TaxCred&Subs'!$E$66:$E$99)*($F35='TaxCred&Subs'!$C$66:$C$99),0)),0)),IF(AND($C35=1,VALUE(RIGHT($AD35,1))>2),(N35-R35)*(IFERROR(INDEX('TaxCred&Subs'!$J$66:$J$99,MATCH(1,($C35&$D35='TaxCred&Subs'!$D$66:$D$99)*($F35='TaxCred&Subs'!$C$66:$C$99),0)),0)),IF($C35>2,(N35-R35)*(IFERROR(INDEX('TaxCred&Subs'!$J$66:$J$99,MATCH(1,($C35&$D35='TaxCred&Subs'!$D$66:$D$99)*($F35='TaxCred&Subs'!$C$66:$C$99),0)),0)),0))),0)} -> 150 | Q35: {=ROUND(IF(AND($C35=2,VALUE(RIGHT($AD35,1))>2),(O35-S35)*(IFERROR(INDEX('TaxCred&Subs'!$J$66:$J$99,MATCH(1,($C35&$D35='TaxCred&Subs'!$E$66:$E$99)*($F35='TaxCred&Subs'!$C$66:$C$99),0)),0)),IF(AND($C35=1,VALUE(RIGHT($AD35,1))>2),(O35-S35)*(IFERROR(INDEX('TaxCred&Subs'!$J$66:$J$99,MATCH(1,($C35&$D35='TaxCred&Subs'!$D$66:$D$99)*($F35='TaxCred&Subs'!$C$66:$C$99),0)),0)),IF($C35>2,(O35-S35)*(IFERROR(INDEX('TaxCred&Subs'!$J$66:$J$99,MATCH(1,($C35&$D35='TaxCred&Subs'!$D$66:$D$99)*($F35='TaxCred&Subs'!$C$66:$C$99),0)),0)),0))),0)} -> 0 | R35: {=ROUND(IF(IFERROR(VALUE(RIGHT($AD35,1)),0)>2,IF($C35=8,N35*IFERROR(INDEX('TaxCred&Subs'!$K$139:$S$151,MATCH($C35&$D35&LEFT($AD35,7),'TaxCred&Subs'!$E$139:$E$151,0),MATCH($H35,'TaxCred&Subs'!$K$137:$S$137,0)),0),IF($C35=2,N35*IFERROR(INDEX('TaxCred&Subs'!$K$139:$S$151,MATCH($C35&$D35,'TaxCred&Subs'!$D$139:$D$151,0),MATCH($H35,'TaxCred&Subs'!$K$137:$S$137,0)),0),N35*IFERROR(INDEX('TaxCred&Subs'!$K$139:$S$151,MATCH($C35&$D35,'TaxCred&Subs'!$C$139:$C$151,0),MATCH($H35,'TaxCred&Subs'!$K$137:$S$137,0)),0))),0),0)} -> 269 | S35: {=ROUND(IF(IFERROR(VALUE(RIGHT($AD35,1)),0)>2,IF($C35=8,O35*IFERROR(INDEX('TaxCred&Subs'!$K$139:$S$151,MATCH($C35&$D35&LEFT($AD35,7),'TaxCred&Subs'!$E$139:$E$151,0),MATCH($H35,'TaxCred&Subs'!$K$137:$S$137,0)),0),IF($C35=2,O35*IFERROR(INDEX('TaxCred&Subs'!$K$139:$S$151,MATCH($C35&$D35,'TaxCred&Subs'!$D$139:$D$151,0),MATCH($H35,'TaxCred&Subs'!$K$137:$S$137,0)),0),O35*IFERROR(INDEX('TaxCred&Subs'!$K$139:$S$151,MATCH($C35&$D35,'TaxCred&Subs'!$C$139:$C$151,0),MATCH($H35,'TaxCred&Subs'!$K$137:$S$137,0)),0))),0),0)} -> 325 | T35: =IF($H35=9,IF(R35>0,(N35-P35)*0.15,0),0) -> 0 | U35: =IF($H35=9,IF(S35>0,(O35-Q35)*0.15,0),0) -> 0 | V35: MATURE | W35: 2020 | X35: 1 | Y35: 0 | Z35: -0.00020762473 | AA35: -0.0031942266 | AB35: 0 | AC35: 0 | AD35: ELEC_HP3
B36: =B35+1 -> 12 | C36: 1 | D36: 2 | E36: 4 | F36: 2020 | G36: 2021 | H36: 4 | I36: 4 | J36: 0 | K36: 0 | L36: 0 | M36: 2.4912075 | N36: 3405 | O36: 4110 | P36: {=ROUND(IF($F36<='TaxCred&Subs'!$C$49,(IF($C36=2,IF($M36>=IFERROR(INDEX('TaxCred&Subs'!$L$12:$L$47,MATCH(1,($C36&$D36='TaxCred&Subs'!$E$12:$E$47)*($F36='TaxCred&Subs'!$C$12:$C$47),0) ),9999),IFERROR(INDEX('TaxCred&Subs'!$N$12:$N$47,MATCH(1,($C36&$D36='TaxCred&Subs'!$E$12:$E$47)*($F36='TaxCred&Subs'!$C$12:$C$47),0) ),0),0),(IF($M36>=IFERROR(INDEX('TaxCred&Subs'!$H$12:$H$47,MATCH(1,($C36&$D36='TaxCred&Subs'!$D$12:$D$47)*($F36='TaxCred&Subs'!$C$12:$C$47),0) ),9999),IFERROR(INDEX('TaxCred&Subs'!$N$12:$N$47,MATCH(1,($C36&$D36='TaxCred&Subs'!$D$12:$D$47)*($F36='TaxCred&Subs'!$C$12:$C$47),0) ),0),0)))),0)+IF(AND($C36=2,VALUE(RIGHT($AD36,1))>2),(N36-R36)*(IFERROR(INDEX('TaxCred&Subs'!$J$66:$J$99,MATCH(1,($C36&$D36='TaxCred&Subs'!$E$66:$E$99)*($F36='TaxCred&Subs'!$C$66:$C$99),0)),0)),IF(AND($C36=1,VALUE(RIGHT($AD36,1))>2),(N36-R36)*(IFERROR(INDEX('TaxCred&Subs'!$J$66:$J$99,MATCH(1,($C36&$D36='TaxCred&Subs'!$D$66:$D$99)*($F36='TaxCred&Subs'!$C$66:$C$99),0)),0)),IF($C36>2,(N36-R36)*(IFERROR(INDEX('TaxCred&Subs'!$J$66:$J$99,MATCH(1,($C36&$D36='TaxCred&Subs'!$D$66:$D$99)*($F36='TaxCred&Subs'!$C$66:$C$99),0)),0)),0))),0)} -> 150 | Q36: {=ROUND(IF(AND($C36=2,VALUE(RIGHT($AD36,1))>2),(O36-S36)*(IFERROR(INDEX('TaxCred&Subs'!$J$66:$J$99,MATCH(1,($C36&$D36='TaxCred&Subs'!$E$66:$E$99)*($F36='TaxCred&Subs'!$C$66:$C$99),0)),0)),IF(AND($C36=1,VALUE(RIGHT($AD36,1))>2),(O36-S36)*(IFERROR(INDEX('TaxCred&Subs'!$J$66:$J$99,MATCH(1,($C36&$D36='TaxCred&Subs'!$D$66:$D$99)*($F36='TaxCred&Subs'!$C$66:$C$99),0)),0)),IF($C36>2,(O36-S36)*(IFERROR(INDEX('TaxCred&Subs'!$J$66:$J$99,MATCH(1,($C36&$D36='TaxCred&Subs'!$D$66:$D$99)*($F36='TaxCred&Subs'!$C$66:$C$99),0)),0)),0))),0)} -> 0 | R36: {=ROUND(IF(IFERROR(VALUE(RIGHT($AD36,1)),0)>2,IF($C36=8,N36*IFERROR(INDEX('TaxCred&Subs'!$K$139:$S$151,MATCH($C36&$D36&LEFT($AD36,7),'TaxCred&Subs'!$E$139:$E$151,0),MATCH($H36,'TaxCred&Subs'!$K$137:$S$137,0)),0),IF($C36=2,N36*IFERROR(INDEX('TaxCred&Subs'!$K$139:$S$151,MATCH($C36&$D36,'TaxCred&Subs'!$D$139:$D$151,0),MATCH($H36,'TaxCred&Subs'!$K$137:$S$137,0)),0),N36*IFERROR(INDEX('TaxCred&Subs'!$K$139:$S$151,MATCH($C36&$D36,'TaxCred&Subs'!$C$139:$C$151,0),MATCH($H36,'TaxCred&Subs'!$K$137:$S$137,0)),0))),0),0)} -> 164 | S36: {=ROUND(IF(IFERROR(VALUE(RIGHT($AD36,1)),0)>2,IF($C36=8,O36*IFERROR(INDEX('TaxCred&Subs'!$K$139:$S$151,MATCH($C36&$D36&LEFT($AD36,7),'TaxCred&Subs'!$E$139:$E$151,0),MATCH($H36,'TaxCred&Subs'!$K$137:$S$137,0)),0),IF($C36=2,O36*IFERROR(INDEX('TaxCred&Subs'!$K$139:$S$151,MATCH($C36&$D36,'TaxCred&Subs'!$D$139:$D$151,0),MATCH($H36,'TaxCred&Subs'!$K$137:$S$137,0)),0),O36*IFERROR(INDEX('TaxCred&Subs'!$K$139:$S$151,MATCH($C36&$D36,'TaxCred&Subs'!$C$139:$C$151,0),MATCH($H36,'TaxCred&Subs'!$K$137:$S$137,0)),0))),0),0)} -> 198 | T36: =IF($H36=9,IF(R36>0,(N36-P36)*0.15,0),0) -> 0 | U36: =IF($H36=9,IF(S36>0,(O36-Q36)*0.15,0),0) -> 0 | V36: MATURE | W36: 2020 | X36: 1 | Y36: 0 | Z36: -0.00020762473 | AA36: -0.0031942266 | AB36: 0 | AC36: 0 | AD36: ELEC_HP3
B37: =B36+1 -> 13 | C37: 1 | D37: 2 | E37: 4 | F37: 2020 | G37: 2021 | H37: 5 | I37: 4 | J37: 0 | K37: 0 | L37: 0 | M37: 2.4912075 | N37: 3405 | O37: 4110 | P37: {=ROUND(IF($F37<='TaxCred&Subs'!$C$49,(IF($C37=2,IF($M37>=IFERROR(INDEX('TaxCred&Subs'!$L$12:$L$47,MATCH(1,($C37&$D37='TaxCred&Subs'!$E$12:$E$47)*($F37='TaxCred&Subs'!$C$12:$C$47),0) ),9999),IFERROR(INDEX('TaxCred&Subs'!$N$12:$N$47,MATCH(1,($C37&$D37='TaxCred&Subs'!$E$12:$E$47)*($F37='TaxCred&Subs'!$C$12:$C$47),0) ),0),0),(IF($M37>=IFERROR(INDEX('TaxCred&Subs'!$H$12:$H$47,MATCH(1,($C37&$D37='TaxCred&Subs'!$D$12:$D$47)*($F37='TaxCred&Subs'!$C$12:$C$47),0) ),9999),IFERROR(INDEX('TaxCred&Subs'!$N$12:$N$47,MATCH(1,($C37&$D37='TaxCred&Subs'!$D$12:$D$47)*($F37='TaxCred&Subs'!$C$12:$C$47),0) ),0),0)))),0)+IF(AND($C37=2,VALUE(RIGHT($AD37,1))>2),(N37-R37)*(IFERROR(INDEX('TaxCred&Subs'!$J$66:$J$99,MATCH(1,($C37&$D37='TaxCred&Subs'!$E$66:$E$99)*($F37='TaxCred&Subs'!$C$66:$C$99),0)),0)),IF(AND($C37=1,VALUE(RIGHT($AD37,1))>2),(N37-R37)*(IFERROR(INDEX('TaxCred&Subs'!$J$66:$J$99,MATCH(1,($C37&$D37='TaxCred&Subs'!$D$66:$D$99)*($F37='TaxCred&Subs'!$C$66:$C$99),0)),0)),IF($C37>2,(N37-R37)*(IFERROR(INDEX('TaxCred&Subs'!$J$66:$J$99,MATCH(1,($C37&$D37='TaxCred&Subs'!$D$66:$D$99)*($F37='TaxCred&Subs'!$C$66:$C$99),0)),0)),0))),0)} -> 150 | Q37: {=ROUND(IF(AND($C37=2,VALUE(RIGHT($AD37,1))>2),(O37-S37)*(IFERROR(INDEX('TaxCred&Subs'!$J$66:$J$99,MATCH(1,($C37&$D37='TaxCred&Subs'!$E$66:$E$99)*($F37='TaxCred&Subs'!$C$66:$C$99),0)),0)),IF(AND($C37=1,VALUE(RIGHT($AD37,1))>2),(O37-S37)*(IFERROR(INDEX('TaxCred&Subs'!$J$66:$J$99,MATCH(1,($C37&$D37='TaxCred&Subs'!$D$66:$D$99)*($F37='TaxCred&Subs'!$C$66:$C$99),0)),0)),IF($C37>2,(O37-S37)*(IFERROR(INDEX('TaxCred&Subs'!$J$66:$J$99,MATCH(1,($C37&$D37='TaxCred&Subs'!$D$66:$D$99)*($F37='TaxCred&Subs'!$C$66:$C$99),0)),0)),0))),0)} -> 0 | R37: {=ROUND(IF(IFERROR(VALUE(RIGHT($AD37,1)),0)>2,IF($C37=8,N37*IFERROR(INDEX('TaxCred&Subs'!$K$139:$S$151,MATCH($C37&$D37&LEFT($AD37,7),'TaxCred&Subs'!$E$139:$E$151,0),MATCH($H37,'TaxCred&Subs'!$K$137:$S$137,0)),0),IF($C37=2,N37*IFERROR(INDEX('TaxCred&Subs'!$K$139:$S$151,MATCH($C37&$D37,'TaxCred&Subs'!$D$139:$D$151,0),MATCH($H37,'TaxCred&Subs'!$K$137:$S$137,0)),0),N37*IFERROR(INDEX('TaxCred&Subs'!$K$139:$S$151,MATCH($C37&$D37,'TaxCred&Subs'!$C$139:$C$151,0),MATCH($H37,'TaxCred&Subs'!$K$137:$S$137,0)),0))),0),0)} -> 74 | S37: {=ROUND(IF(IFERROR(VALUE(RIGHT($AD37,1)),0)>2,IF($C37=8,O37*IFERROR(INDEX('TaxCred&Subs'!$K$139:$S$151,MATCH($C37&$D37&LEFT($AD37,7),'TaxCred&Subs'!$E$139:$E$151,0),MATCH($H37,'TaxCred&Subs'!$K$137:$S$137,0)),0),IF($C37=2,O37*IFERROR(INDEX('TaxCred&Subs'!$K$139:$S$151,MATCH($C37&$D37,'TaxCred&Subs'!$D$139:$D$151,0),MATCH($H37,'TaxCred&Subs'!$K$137:$S$137,0)),0),O37*IFERROR(INDEX('TaxCred&Subs'!$K$139:$S$151,MATCH($C37&$D37,'TaxCred&Subs'!$C$139:$C$151,0),MATCH($H37,'TaxCred&Subs'!$K$137:$S$137,0)),0))),0),0)} -> 90 | T37: =IF($H37=9,IF(R37>0,(N37-P37)*0.15,0),0) -> 0 | U37: =IF($H37=9,IF(S37>0,(O37-Q37)*0.15,0),0) -> 0 | V37: MATURE | W37: 2020 | X37: 1 | Y37: 0 | Z37: -0.00020762473 | AA37: -0.0031942266 | AB37: 0 | AC37: 0 | AD37: ELEC_HP3
... B117: =B116+1 -> 93 | C117: 1 | D117: 3 | E117: 8 | F117: 2022 | G117: 2028 | H117: 9 | I117: 8 | J117: 0 | K117: 0 | L117: 0 | M117: 0.9 | N117: 4130 | O117: 1200 | P117: {=ROUND(IF($F117<='TaxCred&Subs'!$C$49,(IF($C117=2,IF($M117>=IFERROR(INDEX('TaxCred&Subs'!$L$12:$L$47,MATCH(1,($C117&$D117='TaxCred&Subs'!$E$12:$E$47)*($F117='TaxCred&Subs'!$C$12:$C$47),0) ),9999),IFERROR(INDEX('TaxCred&Subs'!$N$12:$N$47,MATCH(1,($C117&$D117='TaxCred&Subs'!$E$12:$E$47)*($F117='TaxCred&Subs'!$C$12:$C$47),0) ),0),0),(IF($M117>=IFERROR(INDEX('TaxCred&Subs'!$H$12:$H$47,MATCH(1,($C117&$D117='TaxCred&Subs'!$D$12:$D$47)*($F117='TaxCred&Subs'!$C$12:$C$47),0) ),9999),IFERROR(INDEX('TaxCred&Subs'!$N$12:$N$47,MATCH(1,($C117&$D117='TaxCred&Subs'!$D$12:$D$47)*($F117='TaxCred&Subs'!$C$12:$C$47),0) ),0),0)))),0)+IF(AND($C117=2,VALUE(RIGHT($AD117,1))>2),(N117-R117)*(IFERROR(INDEX('TaxCred&Subs'!$J$66:$J$99,MATCH(1,($C117&$D117='TaxCred&Subs'!$E$66:$E$99)*($F117='TaxCred&Subs'!$C$66:$C$99),0)),0)),IF(AND($C117=1,VALUE(RIGHT($AD117,1))>2),(N117-R117)*(IFERROR(INDEX('TaxCred&Subs'!$J$66:$J$99,MATCH(1,($C117&$D117='TaxCred&Subs'!$D$66:$D$99)*($F117='TaxCred&Subs'!$C$66:$C$99),0)),0)),IF($C117>2,(N117-R117)*(IFERROR(INDEX('TaxCred&Subs'!$J$66:$J$99,MATCH(1,($C117&$D117='TaxCred&Subs'!$D$66:$D$99)*($F117='TaxCred&Subs'!$C$66:$C$99),0)),0)),0))),0)} -> 0 | Q117: {=ROUND(IF(AND($C117=2,VALUE(RIGHT($AD117,1))>2),(O117-S117)*(IFERROR(INDEX('TaxCred&Subs'!$J$66:$J$99,MATCH(1,($C117&$D117='TaxCred&Subs'!$E$66:$E$99)*($F117='TaxCred&Subs'!$C$66:$C$99),0)),0)),IF(AND($C117=1,VALUE(RIGHT($AD117,1))>2),(O117-S117)*(IFERROR(INDEX('TaxCred&Subs'!$J$66:$J$99,MATCH(1,($C117&$D117='TaxCred&Subs'!$D$66:$D$99)*($F117='TaxCred&Subs'!$C$66:$C$99),0)),0)),IF($C117>2,(O117-S117)*(IFERROR(INDEX('TaxCred&Subs'!$J$66:$J$99,MATCH(1,($C117&$D117='TaxCred&Subs'!$D$66:$D$99)*($F117='TaxCred&Subs'!$C$66:$C$99),0)),0)),0))),0)} -> 0 | R117: {=ROUND(IF(IFERROR(VALUE(RIGHT($AD117,1)),0)>2,IF($C117=8,N117*IFERROR(INDEX('TaxCred&Subs'!$K$139:$S$151,MATCH($C117&$D117&LEFT($AD117,7),'TaxCred&Subs'!$E$139:$E$151,0),MATCH($H117,'TaxCred&Subs'!$K$137:$S$137,0)),0),IF($C117=2,N117*IFERROR(INDEX('TaxCred&Subs'!$K$139:$S$151,MATCH($C117&$D117,'TaxCred&Subs'!$D$139:$D$151,0),MATCH($H117,'TaxCred&Subs'!$K$137:$S$137,0)),0),N117*IFERROR(INDEX('TaxCred&Subs'!$K$139:$S$151,MATCH($C117&$D117,'TaxCred&Subs'!$C$139:$C$151,0),MATCH($H117,'TaxCred&Subs'!$K$137:$S$137,0)),0))),0),0)} -> 624 | S117: {=ROUND(IF(IFERROR(VALUE(RIGHT($AD117,1)),0)>2,IF($C117=8,O117*IFERROR(INDEX('TaxCred&Subs'!$K$139:$S$151,MATCH($C117&$D117&LEFT($AD117,7),'TaxCred&Subs'!$E$139:$E$151,0),MATCH($H117,'TaxCred&Subs'!$K$137:$S$137,0)),0),IF($C117=2,O117*IFERROR(INDEX('TaxCred&Subs'!$K$139:$S$151,MATCH($C117&$D117,'TaxCred&Subs'!$D$139:$D$151,0),MATCH($H117,'TaxCred&Subs'!$K$137:$S$137,0)),0),O117*IFERROR(INDEX('TaxCred&Subs'!$K$139:$S$151,MATCH($C117&$D117,'TaxCred&Subs'!$C$139:$C$151,0),MATCH($H117,'TaxCred&Subs'!$K$137:$S$137,0)),0))),0),0)} -> 181 | T117: =IF($H117=9,IF(R117>0,(N117-P117)*0.15,0),0) -> 619.5 | U117: =IF($H117=9,IF(S117>0,(O117-Q117)*0.15,0),0) -> 180 | V117: MATURE | W117: 2020 | X117: 1 | Y117: 0 | Z117: -0.00021540078 | AA117: -0.0033138581 | AB117: 0 | AC117: 0 | AD117: NG_FA3
